Traceback (most recent call last):
  File "/home/goof/anaconda3/lib/python3.11/site-packages/jupyter_cache/executors/utils.py", line 58, in single_nb_execution
    executenb(
  File "/home/goof/anaconda3/lib/python3.11/site-packages/nbclient/client.py", line 1305, in execute
    return NotebookClient(nb=nb, resources=resources, km=km, **kwargs).execute()
           ^^^^^^^^^^^^^^^^^^^^^^^^^^^^^^^^^^^^^^^^^^^^^^^^^^^^^^^^^^^^^^^^^^^^^
  File "/home/goof/anaconda3/lib/python3.11/site-packages/jupyter_core/utils/__init__.py", line 173, in wrapped
    return loop.run_until_complete(inner)
           ^^^^^^^^^^^^^^^^^^^^^^^^^^^^^^
  File "/home/goof/anaconda3/lib/python3.11/asyncio/base_events.py", line 653, in run_until_complete
    return future.result()
           ^^^^^^^^^^^^^^^
  File "/home/goof/anaconda3/lib/python3.11/site-packages/nbclient/client.py", line 705, in async_execute
    await self.async_execute_cell(
  File "/home/goof/anaconda3/lib/python3.11/site-packages/nbclient/client.py", line 1058, in async_execute_cell
    await self._check_raise_for_error(cell, cell_index, exec_reply)
  File "/home/goof/anaconda3/lib/python3.11/site-packages/nbclient/client.py", line 914, in _check_raise_for_error
    raise CellExecutionError.from_cell_and_msg(cell, exec_reply_content)
nbclient.exceptions.CellExecutionError: An error occurred while executing the following cell:
------------------
import matplotlib.pyplot as plt
import matplotlib.image as mpimg

# Laad de afbeelding
img = mpimg.imread('../data/logo_infovis.png')

# Maak een figuur en een subplot
fig, ax = plt.subplots(figsize=(3, 3))  # Pas de figsize aan om de grootte van de afbeelding te veranderen
ax.imshow(img)
ax.axis('off')  # Verberg de as
ax.set_frame_on(False)  # Verberg de frame rand

# Verwijder alle marges
fig.subplots_adjust(left=0, right=1, top=1, bottom=0, wspace=0, hspace=0)

# Zorg dat de layout van de figuur strak is, zonder extra padding
fig.tight_layout(pad=0)

# Toon de afbeelding
plt.show()
------------------


[0;31m---------------------------------------------------------------------------[0m
[0;31mFileNotFoundError[0m                         Traceback (most recent call last)
Cell [0;32mIn[1], line 5[0m
[1;32m      2[0m [38;5;28;01mimport[39;00m [38;5;21;01mmatplotlib[39;00m[38;5;21;01m.[39;00m[38;5;21;01mimage[39;00m [38;5;28;01mas[39;00m [38;5;21;01mmpimg[39;00m
[1;32m      4[0m [38;5;66;03m# Laad de afbeelding[39;00m
[0;32m----> 5[0m img [38;5;241m=[39m mpimg[38;5;241m.[39mimread([38;5;124m'[39m[38;5;124m../data/logo_infovis.png[39m[38;5;124m'[39m)
[1;32m      7[0m [38;5;66;03m# Maak een figuur en een subplot[39;00m
[1;32m      8[0m fig, ax [38;5;241m=[39m plt[38;5;241m.[39msubplots(figsize[38;5;241m=[39m([38;5;241m3[39m, [38;5;241m3[39m))  [38;5;66;03m# Pas de figsize aan om de grootte van de afbeelding te veranderen[39;00m

File [0;32m~/anaconda3/lib/python3.11/site-packages/matplotlib/image.py:1525[0m, in [0;36mimread[0;34m(fname, format)[0m
[1;32m   1518[0m [38;5;28;01mif[39;00m [38;5;28misinstance[39m(fname, [38;5;28mstr[39m) [38;5;129;01mand[39;00m [38;5;28mlen[39m(parse[38;5;241m.[39murlparse(fname)[38;5;241m.[39mscheme) [38;5;241m>[39m [38;5;241m1[39m:
[1;32m   1519[0m     [38;5;66;03m# Pillow doesn't handle URLs directly.[39;00m
[1;32m   1520[0m     [38;5;28;01mraise[39;00m [38;5;167;01mValueError[39;00m(
[1;32m   1521[0m         [38;5;124m"[39m[38;5;124mPlease open the URL for reading and pass the [39m[38;5;124m"[39m
[1;32m   1522[0m         [38;5;124m"[39m[38;5;124mresult to Pillow, e.g. with [39m[38;5;124m"[39m
[1;32m   1523[0m         [38;5;124m"[39m[38;5;124m``np.array(PIL.Image.open(urllib.request.urlopen(url)))``.[39m[38;5;124m"[39m
[1;32m   1524[0m         )
[0;32m-> 1525[0m [38;5;28;01mwith[39;00m img_open(fname) [38;5;28;01mas[39;00m image:
[1;32m   1526[0m     [38;5;28;01mreturn[39;00m (_pil_png_to_float_array(image)
[1;32m   1527[0m             [38;5;28;01mif[39;00m [38;5;28misinstance[39m(image, PIL[38;5;241m.[39mPngImagePlugin[38;5;241m.[39mPngImageFile) [38;5;28;01melse[39;00m
[1;32m   1528[0m             pil_to_array(image))

File [0;32m~/anaconda3/lib/python3.11/site-packages/PIL/ImageFile.py:105[0m, in [0;36mImageFile.__init__[0;34m(self, fp, filename)[0m
[1;32m    101[0m [38;5;28mself[39m[38;5;241m.[39mdecodermaxblock [38;5;241m=[39m MAXBLOCK
[1;32m    103[0m [38;5;28;01mif[39;00m is_path(fp):
[1;32m    104[0m     [38;5;66;03m# filename[39;00m
[0;32m--> 105[0m     [38;5;28mself[39m[38;5;241m.[39mfp [38;5;241m=[39m [38;5;28mopen[39m(fp, [38;5;124m"[39m[38;5;124mrb[39m[38;5;124m"[39m)
[1;32m    106[0m     [38;5;28mself[39m[38;5;241m.[39mfilename [38;5;241m=[39m fp
[1;32m    107[0m     [38;5;28mself[39m[38;5;241m.[39m_exclusive_fp [38;5;241m=[39m [38;5;28;01mTrue[39;00m

[0;31mFileNotFoundError[0m: [Errno 2] No such file or directory: '../data/logo_infovis.png'

